Traceback (most recent call last):
  File "/home/hoan/Desktop/Malte/MalteVSC/dodo_Genesis_RL/dodo_train.py", line 327, in <module>
    main()
  File "/home/hoan/Desktop/Malte/MalteVSC/dodo_Genesis_RL/dodo_train.py", line 240, in main
    env = DodoEnv(args.num_envs, env_cfg, obs_cfg, reward_cfg, command_cfg)
          ^^^^^^^^^^^^^^^^^^^^^^^^^^^^^^^^^^^^^^^^^^^^^^^^^^^^^^^^^^^^^^^^^
  File "/home/hoan/Desktop/Malte/MalteVSC/dodo_Genesis_RL/dodo_env.py", line 114, in __init__
    self.command_cfg["lin_vel_x_range"][0],
    ~~~~~~~~~~~~~~~~^^^^^^^^^^^^^^^^^^^
KeyError: 'lin_vel_x_range'
Traceback (most recent call last):
  File "/home/hoan/Desktop/Malte/MalteVSC/dodo_Genesis_RL/dodo_train.py", line 327, in <module>
    main()
  File "/home/hoan/Desktop/Malte/MalteVSC/dodo_Genesis_RL/dodo_train.py", line 240, in main
    env = DodoEnv(args.num_envs, env_cfg, obs_cfg, reward_cfg, command_cfg)
          ^^^^^^^^^^^^^^^^^^^^^^^^^^^^^^^^^^^^^^^^^^^^^^^^^^^^^^^^^^^^^^^^^
  File "/home/hoan/Desktop/Malte/MalteVSC/dodo_Genesis_RL/dodo_env.py", line 114, in __init__
    self.command_cfg["lin_vel_x_range"][0],
    ~~~~~~~~~~~~~~~~^^^^^^^^^^^^^^^^^^^
KeyError: 'lin_vel_x_range'

[38;5;9m[Genesis] [14:21:44] [ERROR] KeyError: 'lin_vel_x_range'[0m
